Workbook

Sheet Inicio
A2: NeXo | Prospectos y correos
A3: Base local de negocios de La Dorada, Caldas, con borradores de correo personalizables por sector.
A5: Negocios | C5: Con correo publicado | E5: Sin correo publicado | G5: Categorías
B6: =COUNTA(Contactos!$B$5:$B$225) | D6: =COUNTIF(Contactos!$E$5:$E$225,"<>") | F6: =COUNTBLANK(Contactos!$E$5:$E$225) | H6: =COUNTA(Plantillas!$A$6:$A$15)
A8: Flujo de trabajo
A9: 1. Filtra | B9: En Contactos, usa los filtros de la tabla para elegir una categoría, correo disponible o estado.
A10: 2. Ajusta el mensaje | B10: Edita el asunto y cuerpo de cada sector en Plantillas. Los borradores de Contactos cambian automáticamente; {NEGOCIO} se sustituye por el nombre del prospecto.
A11: 3. Revisa los datos | B11: Confirma que el negocio siga activo, que el correo corresponda y que el contacto comercial sea apropiado antes de enviar.
A12: 4. Prepara la automatización | B12: Procesa solo filas con correo verificado, autorización comercial confirmada y estado Listo para enviar; después registra Enviado y la fecha para evitar duplicados.
A13: 5. Respeta bajas | B13: Si alguien pide no recibir más mensajes, cambia el estado a Dado de baja o No contactar y exclúyelo de cualquier campaña futura.
A14: WhatsApp | B14: Todos los permisos están pendientes según los archivos fuente. No uses teléfonos para publicidad por WhatsApp hasta registrar el consentimiento correspondiente.
A16: Cobertura y fuente
A17: Consolidación | B17: 221 negocios únicos integrados de los dos archivos recibidos; 96 correos publicados y 125 registros sin correo público.
A18: Consulta fuente | B18: La fecha de consulta de los archivos es 19-oct-2026. Las señales de actualidad y enlaces originales se conservan en Contactos.
A19: Validación | B19: La presencia de un contacto público no confirma que siga vigente ni que pueda usarse para cualquier campaña. Verifica cada registro y aplica las reglas de contacto y baja correspondientes.

Sheet Contactos
A2: Base de contactos de La Dorada
A3: Filtra por categoría o correo. Asunto y cuerpo salen de Plantillas; haz clic en la celda para copiar el texto completo. Las celdas amarillas son controles editables.
A4: ID | B4: Negocio | C4: Categoría de contacto | D4: Sector según fuente | E4: Correo público | F4: Teléfono público | G4: Dirección publicada | H4: Fecha de consulta | I4: Indicio de actualidad | J4: Fuente pública | K4: Observaciones de la fuente | L4: Asunto sugerido | M4: Cuerpo sugerido | N4: Validación del correo | O4: Autorización comercial | P4: Estado de campaña | Q4: Fecha de envío | R4: Resultado / notas | S4: WhatsApp autorizado
A5: NX-001 | B5: EL SOL DORADO | C5: Hoteles y hospedajes | D5: Hotel / hospedaje | E5: hotelsoldoradoladorada@gmail.com | F5: 3103726898 | G5: K 1 14 44 | H5: 46314 | I5: Sin señal de actualización específica en el registro fuente; verificar vigencia. | J5: https://www.datos.gov.co/w/m463-yj48/dneh-mcp2 | K5: Registro del directorio público de hoteles; confirmar vigencia y datos antes de contactar. Dirección conservada en el formato abreviado de la fuente. | Fuente: Prospectos_NeXo_La_Dorada.xlsx | L5: =IF($B5="","",SUBSTITUTE(INDEX(Plantillas!$B$6:$B$15,MATCH($C5,Plantillas!$A$6:$A$15,0)),"{NEGOCIO}",$B5)) | M5: =IF($B5="","",SUBSTITUTE(INDEX(Plantillas!$C$6:$C$15,MATCH($C5,Plantillas!$A$6:$A$15,0)),"{NEGOCIO}",$B5)) | N5: Pendiente de verificar | O5: Pendiente de revisar | P5: Enviado | Q5: 2026-10-21 14:02:23 | R5: Enviado con éxito a: hotelsoldoradoladorada@gmail.com | S5: Pendiente
A6: NX-002 | B6: MALL SANTANA DEL RÍO | C6: Hoteles y hospedajes | D6: Hotel / hospedaje | E6: reservas@hotelsantanadelrio.com | F6: 3126777777 | G6: C 13 K 1 | H6: 46314 | I6: Sin señal de actualización específica en el registro fuente; verificar vigencia. | J6: https://www.datos.gov.co/w/m463-yj48/dneh-mcp2 | K6: Registro del directorio público de hoteles; confirmar vigencia y datos antes de contactar. Dirección conservada en el formato abreviado de la fuente. | Fuente: Prospectos_NeXo_La_Dorada.xlsx | L6: =IF($B6="","",SUBSTITUTE(INDEX(Plantillas!$B$6:$B$15,MATCH($C6,Plantillas!$A$6:$A$15,0)),"{NEGOCIO}",$B6)) | M6: =IF($B6="","",SUBSTITUTE(INDEX(Plantillas!$C$6:$C$15,MATCH($C6,Plantillas!$A$6:$A$15,0)),"{NEGOCIO}",$B6)) | N6: Pendiente de verificar | O6: Pendiente de revisar | P6: Enviado | Q6: 2026-10-21 14:03:26 | R6: Enviado con éxito a: reservas@hotelsantanadelrio.com | S6: Pendiente
A7: NX-003 | B7: APARTAHOTEL AUTOMATICO | C7: Hoteles y hospedajes | D7: Hotel / hospedaje | E7: osorio1023@hotmail.com | F7: 3147936195 | G7: K 2 13 04 | H7: 46314 | I7: Sin señal de actualización específica en el registro fuente; verificar vigencia. | J7: https://www.datos.gov.co/w/m463-yj48/dneh-mcp2 | K7: Registro del directorio público de hoteles; confirmar vigencia y datos antes de contactar. Dirección conservada en el formato abreviado de la fuente. | Fuente: Prospectos_NeXo_La_Dorada.xlsx | L7: =IF($B7="","",SUBSTITUTE(INDEX(Plantillas!$B$6:$B$15,MATCH($C7,Plantillas!$A$6:$A$15,0)),"{NEGOCIO}",$B7)) | M7: =IF($B7="","",SUBSTITUTE(INDEX(Plantillas!$C$6:$C$15,MATCH($C7,Plantillas!$A$6:$A$15,0)),"{NEGOCIO}",$B7)) | N7: Pendiente de verificar | O7: Pendiente de revisar | P7: Pendiente de revisión | S7: Pendiente
A8: NX-004 | B8: SOROCAIMA | C8: Hoteles y hospedajes | D8: Hotel / hospedaje | E8: ivanchavarro@hotmail.com | F8: 3218072460 | G8: K 2 14 17 | H8: 46314 | I8: Sin señal de actualización específica en el registro fuente; verificar vigencia. | J8: https://www.datos.gov.co/w/m463-yj48/dneh-mcp2 | K8: Registro del directorio público de hoteles; confirmar vigencia y datos antes de contactar. Dirección conservada en el formato abreviado de la fuente. | Fuente: Prospectos_NeXo_La_Dorada.xlsx | L8: =IF($B8="","",SUBSTITUTE(INDEX(Plantillas!$B$6:$B$15,MATCH($C8,Plantillas!$A$6:$A$15,0)),"{NEGOCIO}",$B8)) | M8: =IF($B8="","",SUBSTITUTE(INDEX(Plantillas!$C$6:$C$15,MATCH($C8,Plantillas!$A$6:$A$15,0)),"{NEGOCIO}",$B8)) | N8: Pendiente de verificar | O8: Pendiente de revisar | P8: Pendiente de revisión | S8: Pendiente
A9: NX-005 | B9: RESORT COLOMBIA | C9: Hoteles y hospedajes | D9: Hotel / hospedaje | E9: resortcolombia@hotmail.com | F9: 3107685708 | G9: K 3 13 40 | H9: 46314 | I9: Sin señal de actualización específica en el registro fuente; verificar vigencia. | J9: https://www.datos.gov.co/w/m463-yj48/dneh-mcp2 | K9: Registro del directorio público de hoteles; confirmar vigencia y datos antes de contactar. Dirección conservada en el formato abreviado de la fuente. | Fuente: Prospectos_NeXo_La_Dorada.xlsx | L9: =IF($B9="","",SUBSTITUTE(INDEX(Plantillas!$B$6:$B$15,MATCH($C9,Plantillas!$A$6:$A$15,0)),"{NEGOCIO}",$B9)) | M9: =IF($B9="","",SUBSTITUTE(INDEX(Plantillas!$C$6:$C$15,MATCH($C9,Plantillas!$A$6:$A$15,0)),"{NEGOCIO}",$B9)) | N9: Pendiente de verificar | O9: Pendiente de revisar | P9: Pendiente de revisión | S9: Pendiente
A10: NX-006 | B10: EL MESON | C10: Hoteles y hospedajes | D10: Hotel / hospedaje | E10: gerencia@hotelelmeson.com | F10: 3146000000 | G10: K 3 15 61 | H10: 46314 | I10: Sin señal de actualización específica en el registro fuente; verificar vigencia. | J10: https://www.datos.gov.co/w/m463-yj48/dneh-mcp2 | K10: Registro del directorio público de hoteles; confirmar vigencia y datos antes de contactar. Dirección conservada en el formato abreviado de la fuente. | Fuente: Prospectos_NeXo_La_Dorada.xlsx | L10: =IF($B10="","",SUBSTITUTE(INDEX(Plantillas!$B$6:$B$15,MATCH($C10,Plantillas!$A$6:$A$15,0)),"{NEGOCIO}",$B10)) | M10: =IF($B10="","",SUBSTITUTE(INDEX(Plantillas!$C$6:$C$15,MATCH($C10,Plantillas!$A$6:$A$15,0)),"{NEGOCIO}",$B10)) | N10: Pendiente de verificar | O10: Pendiente de revisar | P10: Pendiente de revisión | S10: Pendiente
A11: NX-007 | B11: BOLÍVAR PLAZA | C11: Hoteles y hospedajes | D11: Hotel / hospedaje | E11: reservas@hotelesbolivarplaza.com | F11: 3218019705 | G11: C 16 2 38 | H11: 46314 | I11: Sin señal de actualización específica en el registro fuente; verificar vigencia. | J11: https://www.datos.gov.co/w/m463-yj48/dneh-mcp2 | K11: Registro del directorio público de hoteles; confirmar vigencia y datos antes de contactar. Dirección conservada en el formato abreviado de la fuente. | Fuente: Prospectos_NeXo_La_Dorada.xlsx | L11: =IF($B11="","",SUBSTITUTE(INDEX(Plantillas!$B$6:$B$15,MATCH($C11,Plantillas!$A$6:$A$15,0)),"{NEGOCIO}",$B11)) | M11: =IF($B11="","",SUBSTITUTE(INDEX(Plantillas!$C$6:$C$15,MATCH($C11,Plantillas!$A$6:$A$15,0)),"{NEGOCIO}",$B11)) | N11: Pendiente de verificar | O11: Pendiente de revisar | P11: Pendiente de revisión | S11: Pendiente
A12: NX-008 | B12: MI CASITA | C12: Hoteles y hospedajes | D12: Hotel / hospedaje | E12: hotelfamiliarmicasitajm1975@gmail.com | F12: 3138107714 | G12: C 16 2 56 | H12: 46314 | I12: Sin señal de actualización específica en el registro fuente; verificar vigencia. | J12: https://www.datos.gov.co/w/m463-yj48/dneh-mcp2 | K12: Registro del directorio público de hoteles; confirmar vigencia y datos antes de contactar. Dirección conservada en el formato abreviado de la fuente. | Fuente: Prospectos_NeXo_La_Dorada.xlsx | L12: =IF($B12="","",SUBSTITUTE(INDEX(Plantillas!$B$6:$B$15,MATCH($C12,Plantillas!$A$6:$A$15,0)),"{NEGOCIO}",$B12)) | M12: =IF($B12="","",SUBSTITUTE(INDEX(Plantillas!$C$6:$C$15,MATCH($C12,Plantillas!$A$6:$A$15,0)),"{NEGOCIO}",$B12)) | N12: Pendiente de verificar | O12: Pendiente de revisar | P12: Pendiente de revisión | S12: Pendiente
A13: NX-009 | B13: LUMARAC | C13: Hoteles y hospedajes | D13: Hotel / hospedaje | E13: niercusa@hotmail.com | F13: 3146516110 | G13: C 16 2 48 | H13: 46314 | I13: Sin señal de actualización específica en el registro fuente; verificar vigencia. | J13: https://www.datos.gov.co/w/m463-yj48/dneh-mcp2 | K13: Registro del directorio público de hoteles; confirmar vigencia y datos antes de contactar. Dirección conservada en el formato abreviado de la fuente. | Fuente: Prospectos_NeXo_La_Dorada.xlsx | L13: =IF($B13="","",SUBSTITUTE(INDEX(Plantillas!$B$6:$B$15,MATCH($C13,Plantillas!$A$6:$A$15,0)),"{NEGOCIO}",$B13)) | M13: =IF($B13="","",SUBSTITUTE(INDEX(Plantillas!$C$6:$C$15,MATCH($C13,Plantillas!$A$6:$A$15,0)),"{NEGOCIO}",$B13)) | N13: Pendiente de verificar | O13: Pendiente de revisar | P13: Pendiente de revisión | S13: Pendiente
A14: NX-010 | B14: EL PALACIO | C14: Hoteles y hospedajes | D14: Hotel / hospedaje | E14: robinsonagudelo2010@gmail.com | F14: 3228347900 | G14: K 2 16 25 | H14: 46314 | I14: Sin señal de actualización específica en el registro fuente; verificar vigencia. | J14: https://www.datos.gov.co/w/m463-yj48/dneh-mcp2 | K14: Registro del directorio público de hoteles; confirmar vigencia y datos antes de contactar. Dirección conservada en el formato abreviado de la fuente. | Fuente: Prospectos_NeXo_La_Dorada.xlsx | L14: =IF($B14="","",SUBSTITUTE(INDEX(Plantillas!$B$6:$B$15,MATCH($C14,Plantillas!$A$6:$A$15,0)),"{NEGOCIO}",$B14)) | M14: =IF($B14="","",SUBSTITUTE(INDEX(Plantillas!$C$6:$C$15,MATCH($C14,Plantillas!$A$6:$A$15,0)),"{NEGOCIO}",$B14)) | N14: Pendiente de verificar | O14: Pendiente de revisar | P14: Pendiente de revisión | S14: Pendiente
A15: NX-011 | B15: BELLA ISA | C15: Hoteles y hospedajes | D15: Hotel / hospedaje | E15: hotelbellaisa@gmail.com | F15: 3205579451 | G15: K 2 18 33 | H15: 46314 | I15: Sin señal de actualización específica en el registro fuente; verificar vigencia. | J15: https://www.datos.gov.co/w/m463-yj48/dneh-mcp2 | K15: Registro del directorio público de hoteles; confirmar vigencia y datos antes de contactar. Dirección conservada en el formato abreviado de la fuente. | Fuente: Prospectos_NeXo_La_Dorada.xlsx | L15: =IF($B15="","",SUBSTITUTE(INDEX(Plantillas!$B$6:$B$15,MATCH($C15,Plantillas!$A$6:$A$15,0)),"{NEGOCIO}",$B15)) | M15: =IF($B15="","",SUBSTITUTE(INDEX(Plantillas!$C$6:$C$15,MATCH($C15,Plantillas!$A$6:$A$15,0)),"{NEGOCIO}",$B15)) | N15: Pendiente de verificar | O15: Pendiente de revisar | P15: Pendiente de revisión | S15: Pendiente
A16: NX-012 | B16: COUNTRY PLAZA | C16: Hoteles y hospedajes | D16: Hotel / hospedaje | E16: jhonvivarez@gmail.com | F16: 3218020900 | G16: K 2 16 57 | H16: 46314 | I16: Sin señal de actualización específica en el registro fuente; verificar vigencia. | J16: https://www.datos.gov.co/w/m463-yj48/dneh-mcp2 | K16: Registro del directorio público de hoteles; confirmar vigencia y datos antes de contactar. Dirección conservada en el formato abreviado de la fuente. | Fuente: Prospectos_NeXo_La_Dorada.xlsx | L16: =IF($B16="","",SUBSTITUTE(INDEX(Plantillas!$B$6:$B$15,MATCH($C16,Plantillas!$A$6:$A$15,0)),"{NEGOCIO}",$B16)) | M16: =IF($B16="","",SUBSTITUTE(INDEX(Plantillas!$C$6:$C$15,MATCH($C16,Plantillas!$A$6:$A$15,0)),"{NEGOCIO}",$B16)) | N16: Pendiente de verificar | O16: Pendiente de revisar | P16: Pendiente de revisión | S16: Pendiente
A17: NX-013 | B17: RESIDENCIAS BOGOTÁ | C17: Hoteles y hospedajes | D17: Hotel / hospedaje | E17: evelioaaron12@gmail.com | F17: 3147027029 | G17: K 2 20 23 | H17: 46314 | I17: Sin señal de actualización específica en el registro fuente; verificar vigencia. | J17: https://www.datos.gov.co/w/m463-yj48/dneh-mcp2 | K17: Registro del directorio público de hoteles; confirmar vigencia y datos antes de contactar. Dirección conservada en el formato abreviado de la fuente. | Fuente: Prospectos_NeXo_La_Dorada.xlsx | L17: =IF($B17="","",SUBSTITUTE(INDEX(Plantillas!$B$6:$B$15,MATCH($C17,Plantillas!$A$6:$A$15,0)),"{NEGOCIO}",$B17)) | M17: =IF($B17="","",SUBSTITUTE(INDEX(Plantillas!$C$6:$C$15,MATCH($C17,Plantillas!$A$6:$A$15,0)),"{NEGOCIO}",$B17)) | N17: Pendiente de verificar | O17: Pendiente de revisar | P17: Pendiente de revisión | S17: Pendiente
A18: NX-014 | B18: RUTA DORADA | C18: Hoteles y hospedajes | D18: Hotel / hospedaje | F18: 3218007674 | G18: C 17 2 40 | H18: 46314 | I18: Sin señal de actualización específica en el registro fuente; verificar vigencia. | J18: https://www.datos.gov.co/w/m463-yj48/dneh-mcp2 | K18: Registro del directorio público de hoteles; confirmar vigencia y datos antes de contactar. Dirección conservada en el formato abreviado de la fuente. | Fuente: Prospectos_NeXo_La_Dorada.xlsx | L18: =IF($B18="","",SUBSTITUTE(INDEX(Plantillas!$B$6:$B$15,MATCH($C18,Plantillas!$A$6:$A$15,0)),"{NEGOCIO}",$B18)) | M18: =IF($B18="","",SUBSTITUTE(INDEX(Plantillas!$C$6:$C$15,MATCH($C18,Plantillas!$A$6:$A$15,0)),"{NEGOCIO}",$B18)) | N18: Sin correo público | O18: Pendiente de revisar | P18: Pendiente de revisión | S18: Pendiente
A19: NX-015 | B19: EL PORTAL DE LA DORADA | C19: Hoteles y hospedajes | D19: Hotel / hospedaje | E19: gerhotelelportaldeladorada@gmail.com | F19: 3218117925 | G19: K 3 17 43 | H19: 46314 | I19: Sin señal de actualización específica en el registro fuente; verificar vigencia. | J19: https://www.datos.gov.co/w/m463-yj48/dneh-mcp2 | K19: Registro del directorio público de hoteles; confirmar vigencia y datos antes de contactar. Dirección conservada en el formato abreviado de la fuente. Cotelco publica una variante de correo/dirección; verificar el dato. | Fuente: Prospectos_NeXo_La_Dorada.xlsx | L19: =IF($B19="","",SUBSTITUTE(INDEX(Plantillas!$B$6:$B$15,MATCH($C19,Plantillas!$A$6:$A$15,0)),"{NEGOCIO}",$B19)) | M19: =IF($B19="","",SUBSTITUTE(INDEX(Plantillas!$C$6:$C$15,MATCH($C19,Plantillas!$A$6:$A$15,0)),"{NEGOCIO}",$B19)) | N19: Pendiente de verificar | O19: Pendiente de revisar | P19: Pendiente de revisión | S19: Pendiente
A20: NX-016 | B20: EL PALMAR DE LA DORADA | C20: Hoteles y hospedajes | D20: Hotel / hospedaje | E20: olaya1953@hotmail.com | F20: 3116091174 | G20: SALIDA HONDA | H20: 46314 | I20: Sin señal de actualización específica en el registro fuente; verificar vigencia. | J20: https://www.datos.gov.co/w/m463-yj48/dneh-mcp2 | K20: Registro del directorio público de hoteles; confirmar vigencia y datos antes de contactar. Dirección conservada en el formato abreviado de la fuente. | Fuente: Prospectos_NeXo_La_Dorada.xlsx | L20: =IF($B20="","",SUBSTITUTE(INDEX(Plantillas!$B$6:$B$15,MATCH($C20,Plantillas!$A$6:$A$15,0)),"{NEGOCIO}",$B20)) | M20: =IF($B20="","",SUBSTITUTE(INDEX(Plantillas!$C$6:$C$15,MATCH($C20,Plantillas!$A$6:$A$15,0)),"{NEGOCIO}",$B20)) | N20: Pendiente de verificar | O20: Pendiente de revisar | P20: Pendiente de revisión | S20: Pendiente
A21: NX-017 | B21: LA MELISSA | C21: Hoteles y hospedajes | D21: Hotel / hospedaje | E21: lamelissa20040@yahoo.es | F21: 3103522280 | G21: C 11 K 15 | H21: 46314 | I21: Sin señal de actualización específica en el registro fuente; verificar vigencia. | J21: https://www.datos.gov.co/w/m463-yj48/dneh-mcp2 | K21: Registro del directorio público de hoteles; confirmar vigencia y datos antes de contactar. Dirección conservada en el formato abreviado de la fuente. | Fuente: Prospectos_NeXo_La_Dorada.xlsx | L21: =IF($B21="","",SUBSTITUTE(INDEX(Plantillas!$B$6:$B$15,MATCH($C21,Plantillas!$A$6:$A$15,0)),"{NEGOCIO}",$B21)) | M21: =IF($B21="","",SUBSTITUTE(INDEX(Plantillas!$C$6:$C$15,MATCH($C21,Plantillas!$A$6:$A$15,0)),"{NEGOCIO}",$B21)) | N21: Pendiente de verificar | O21: Pendiente de revisar | P21: Pendiente de revisión | S21: Pendiente
A22: NX-018 | B22: BRISAS DEL RECUERDO | C22: Hoteles y hospedajes | D22: Hotel / hospedaje | E22: osdumo@yahoo.es | F22: 3117914842 | G22: K 15 16 18 | H22: 46314 | I22: Sin señal de actualización específica en el registro fuente; verificar vigencia. | J22: https://www.datos.gov.co/w/m463-yj48/dneh-mcp2 | K22: Registro del directorio público de hoteles; confirmar vigencia y datos antes de contactar. Dirección conservada en el formato abreviado de la fuente. | Fuente: Prospectos_NeXo_La_Dorada.xlsx | L22: =IF($B22="","",SUBSTITUTE(INDEX(Plantillas!$B$6:$B$15,MATCH($C22,Plantillas!$A$6:$A$15,0)),"{NEGOCIO}",$B22)) | M22: =IF($B22="","",SUBSTITUTE(INDEX(Plantillas!$C$6:$C$15,MATCH($C22,Plantillas!$A$6:$A$15,0)),"{NEGOCIO}",$B22)) | N22: Pendiente de verificar | O22: Pendiente de revisar | P22: Pendiente de revisión | S22: Pendiente
A23: NX-019 | B23: LA MANSIÓN | C23: Hoteles y hospedajes | D23: Hotel / hospedaje | E23: deypepa@yahoo.es | F23: 3105436376 | G23: K 15 16 38 | H23: 46314 | I23: Sin señal de actualización específica en el registro fuente; verificar vigencia. | J23: https://www.datos.gov.co/w/m463-yj48/dneh-mcp2 | K23: Registro del directorio público de hoteles; confirmar vigencia y datos antes de contactar. Dirección conservada en el formato abreviado de la fuente. | Fuente: Prospectos_NeXo_La_Dorada.xlsx | L23: =IF($B23="","",SUBSTITUTE(INDEX(Plantillas!$B$6:$B$15,MATCH($C23,Plantillas!$A$6:$A$15,0)),"{NEGOCIO}",$B23)) | M23: =IF($B23="","",SUBSTITUTE(INDEX(Plantillas!$C$6:$C$15,MATCH($C23,Plantillas!$A$6:$A$15,0)),"{NEGOCIO}",$B23)) | N23: Pendiente de verificar | O23: Pendiente de revisar | P23: Pendiente de revisión | S23: Pendiente
A24: NX-020 | B24: ZONA TROPICAL | C24: Hoteles y hospedajes | D24: Hotel / hospedaje | E24: hotelzonatropical@hotmail.com | F24: 3117929210 | G24: C 11 12 27 | H24: 46314 | I24: Sin señal de actualización específica en el registro fuente; verificar vigencia. | J24: https://www.datos.gov.co/w/m463-yj48/dneh-mcp2 | K24: Registro del directorio público de hoteles; confirmar vigencia y datos antes de contactar. Dirección conservada en el formato abreviado de la fuente. | Fuente: Prospectos_NeXo_La_Dorada.xlsx | L24: =IF($B24="","",SUBSTITUTE(INDEX(Plantillas!$B$6:$B$15,MATCH($C24,Plantillas!$A$6:$A$15,0)),"{NEGOCIO}",$B24)) | M24: =IF($B24="","",SUBSTITUTE(INDEX(Plantillas!$C$6:$C$15,MATCH($C24,Plantillas!$A$6:$A$15,0)),"{NEGOCIO}",$B24)) | N24: Pendiente de verificar | O24: Pendiente de revisar | P24: Pendiente de revisión | S24: Pendiente
A25: NX-021 | B25: MONTANAR | C25: Hoteles y hospedajes | D25: Hotel / hospedaje | E25: montanarhotel@gmail.com | F25: 3108442641 | G25: C 10 7 46 | H25: 46314 | I25: Sin señal de actualización específica en el registro fuente; verificar vigencia. | J25: https://www.datos.gov.co/w/m463-yj48/dneh-mcp2 | K25: Registro del directorio público de hoteles; confirmar vigencia y datos antes de contactar. Dirección conservada en el formato abreviado de la fuente. | Fuente: Prospectos_NeXo_La_Dorada.xlsx | L25: =IF($B25="","",SUBSTITUTE(INDEX(Plantillas!$B$6:$B$15,MATCH($C25,Plantillas!$A$6:$A$15,0)),"{NEGOCIO}",$B25)) | M25: =IF($B25="","",SUBSTITUTE(INDEX(Plantillas!$C$6:$C$15,MATCH($C25,Plantillas!$A$6:$A$15,0)),"{NEGOCIO}",$B25)) | N25: Pendiente de verificar | O25: Pendiente de revisar | P25: Pendiente de revisión | S25: Pendiente
A26: NX-022 | B26: APARTAESTUDIOS CONFORT | C26: Hoteles y hospedajes | D26: Hotel / hospedaje | E26: hotelconfort2016@hotmail.com | F26: 3226866448 | G26: C 10 6 35 | H26: 46314 | I26: Sin señal de actualización específica en el registro fuente; verificar vigencia. | J26: https://www.datos.gov.co/w/m463-yj48/dneh-mcp2 | K26: Registro del directorio público de hoteles; confirmar vigencia y datos antes de contactar. Dirección conservada en el formato abreviado de la fuente. | Fuente: Prospectos_NeXo_La_Dorada.xlsx | L26: =IF($B26="","",SUBSTITUTE(INDEX(Plantillas!$B$6:$B$15,MATCH($C26,Plantillas!$A$6:$A$15,0)),"{NEGOCIO}",$B26)) | M26: =IF($B26="","",SUBSTITUTE(INDEX(Plantillas!$C$6:$C$15,MATCH($C26,Plantillas!$A$6:$A$15,0)),"{NEGOCIO}",$B26)) | N26: Pendiente de verificar | O26: Pendiente de revisar | P26: Pendiente de revisión | S26: Pendiente
A27: NX-023 | B27: MONTEVERDE | C27: Hoteles y hospedajes | D27: Hotel / hospedaje | E27: monteverdehotel1@hotmail.com | F27: 3127931922 | G27: K 6 10 43 | H27: 46314 | I27: Sin señal de actualización específica en el registro fuente; verificar vigencia. | J27: https://www.datos.gov.co/w/m463-yj48/dneh-mcp2 | K27: Registro del directorio público de hoteles; confirmar vigencia y datos antes de contactar. Dirección conservada en el formato abreviado de la fuente. | Fuente: Prospectos_NeXo_La_Dorada.xlsx | L27: =IF($B27="","",SUBSTITUTE(INDEX(Plantillas!$B$6:$B$15,MATCH($C27,Plantillas!$A$6:$A$15,0)),"{NEGOCIO}",$B27)) | M27: =IF($B27="","",SUBSTITUTE(INDEX(Plantillas!$C$6:$C$15,MATCH($C27,Plantillas!$A$6:$A$15,0)),"{NEGOCIO}",$B27)) | N27: Pendiente de verificar | O27: Pendiente de revisar | P27: Pendiente de revisión | S27: Pendiente
A28: NX-024 | B28: TRAMONTI | C28: Hoteles y hospedajes | D28: Hotel / hospedaje | E28: laura_naranjo25@hotmail.com | F28: 3116434714 | G28: K 4 10 51 | H28: 46314 | I28: Sin señal de actualización específica en el registro fuente; verificar vigencia. | J28: https://www.datos.gov.co/w/m463-yj48/dneh-mcp2 | K28: Registro del directorio público de hoteles; confirmar vigencia y datos antes de contactar. Dirección conservada en el formato abreviado de la fuente. | Fuente: Prospectos_NeXo_La_Dorada.xlsx | L28: =IF($B28="","",SUBSTITUTE(INDEX(Plantillas!$B$6:$B$15,MATCH($C28,Plantillas!$A$6:$A$15,0)),"{NEGOCIO}",$B28)) | M28: =IF($B28="","",SUBSTITUTE(INDEX(Plantillas!$C$6:$C$15,MATCH($C28,Plantillas!$A$6:$A$15,0)),"{NEGOCIO}",$B28)) | N28: Pendiente de verificar | O28: Pendiente de revisar | P28: Pendiente de revisión | S28: Pendiente
A29: NX-025 | B29: MI CHOCITA | C29: Hoteles y hospedajes | D29: Hotel / hospedaje | E29: hotelmichocitadorada@hotmail.com | F29: 3206339035 | G29: K 2 6 17 | H29: 46314 | I29: Sin señal de actualización específica en el registro fuente; verificar vigencia. | J29: https://www.datos.gov.co/w/m463-yj48/dneh-mcp2 | K29: Registro del directorio público de hoteles; confirmar vigencia y datos antes de contactar. Dirección conservada en el formato abreviado de la fuente. | Fuente: Prospectos_NeXo_La_Dorada.xlsx | L29: =IF($B29="","",SUBSTITUTE(INDEX(Plantillas!$B$6:$B$15,MATCH($C29,Plantillas!$A$6:$A$15,0)),"{NEGOCIO}",$B29)) | M29: =IF($B29="","",SUBSTITUTE(INDEX(Plantillas!$C$6:$C$15,MATCH($C29,Plantillas!$A$6:$A$15,0)),"{NEGOCIO}",$B29)) | N29: Pendiente de verificar | O29: Pendiente de revisar | P29: Pendiente de revisión | S29: Pendiente
A30: NX-026 | B30: DORADA PLAZA | C30: Hoteles y hospedajes | D30: Hotel / hospedaje | E30: hoteldoradaplaza@hotmail.com | F30: 3148627715 | G30: C 14 3 65 | H30: 46314 | I30: Sin señal de actualización específica en el registro fuente; verificar vigencia. | J30: https://www.datos.gov.co/w/m463-yj48/dneh-mcp2 | K30: Registro del directorio público de hoteles; confirmar vigencia y datos antes de contactar. Dirección conservada en el formato abreviado de la fuente. | Fuente: Prospectos_NeXo_La_Dorada.xlsx | L30: =IF($B30="","",SUBSTITUTE(INDEX(Plantillas!$B$6:$B$15,MATCH($C30,Plantillas!$A$6:$A$15,0)),"{NEGOCIO}",$B30)) | M30: =IF($B30="","",SUBSTITUTE(INDEX(Plantillas!$C$6:$C$15,MATCH($C30,Plantillas!$A$6:$A$15,0)),"{NEGOCIO}",$B30)) | N30: Pendiente de verificar | O30: Pendiente de revisar | P30: Pendiente de revisión | S30: Pendiente
... A72: NX-068 | B72: HOSPEDAJE DOÑA LUZ MILA | C72: Hoteles y hospedajes | D72: Hotel / hospedaje | E72: clausanalejo326@hotmail.com | F72: 3136283962 | G72: C 11 13 34 | H72: 46314 | I72: Sin señal de actualización específica en el registro fuente; verificar vigencia. | J72: https://www.datos.gov.co/w/m463-yj48/dneh-mcp2 | K72: Registro del directorio público de hoteles; confirmar vigencia y datos antes de contactar. Dirección conservada en el formato abreviado de la fuente. | Fuente: Prospectos_NeXo_La_Dorada.xlsx | L72: =IF($B72="","",SUBSTITUTE(INDEX(Plantillas!$B$6:$B$15,MATCH($C72,Plantillas!$A$6:$A$15,0)),"{NEGOCIO}",$B72)) | M72: =IF($B72="","",SUBSTITUTE(INDEX(Plantillas!$C$6:$C$15,MATCH($C72,Plantillas!$A$6:$A$15,0)),"{NEGOCIO}",$B72)) | N72: Pendiente de verificar | O72: Pendiente de revisar | P72: Pendiente de revisión | S72: Pendiente
A73: NX-069 | B73: RESIDENCIAS LAS MALVINAS | C73: Hoteles y hospedajes | D73: Hotel / hospedaje | F73: 3113013104 | G73: C 19 3 30 | H73: 46314 | I73: Sin señal de actualización específica en el registro fuente; verificar vigencia. | J73: https://www.datos.gov.co/w/m463-yj48/dneh-mcp2 | K73: Registro del directorio público de hoteles; confirmar vigencia y datos antes de contactar. Dirección conservada en el formato abreviado de la fuente. | Fuente: Prospectos_NeXo_La_Dorada.xlsx | L73: =IF($B73="","",SUBSTITUTE(INDEX(Plantillas!$B$6:$B$15,MATCH($C73,Plantillas!$A$6:$A$15,0)),"{NEGOCIO}",$B73)) | M73: =IF($B73="","",SUBSTITUTE(INDEX(Plantillas!$C$6:$C$15,MATCH($C73,Plantillas!$A$6:$A$15,0)),"{NEGOCIO}",$B73)) | N73: Sin correo público | O73: Pendiente de revisar | P73: Pendiente de revisión | S73: Pendiente
A74: NX-070 | B74: POSADA TURISTICA BUENAVISTA | C74: Hoteles y hospedajes | D74: Hotel / hospedaje | E74: apbbuenavista@gmail.com | F74: 3164050918 | G74: BUENAVISTA | H74: 46314 | I74: Sin señal de actualización específica en el registro fuente; verificar vigencia. | J74: https://www.datos.gov.co/w/m463-yj48/dneh-mcp2 | K74: Registro del directorio público de hoteles; confirmar vigencia y datos antes de contactar. Dirección conservada en el formato abreviado de la fuente. | Fuente: Prospectos_NeXo_La_Dorada.xlsx | L74: =IF($B74="","",SUBSTITUTE(INDEX(Plantillas!$B$6:$B$15,MATCH($C74,Plantillas!$A$6:$A$15,0)),"{NEGOCIO}",$B74)) | M74: =IF($B74="","",SUBSTITUTE(INDEX(Plantillas!$C$6:$C$15,MATCH($C74,Plantillas!$A$6:$A$15,0)),"{NEGOCIO}",$B74)) | N74: Pendiente de verificar | O74: Pendiente de revisar | P74: Pendiente de revisión | S74: Pendiente
A75: NX-071 | B75: CABAÑA DE GEORGE | C75: Hoteles y hospedajes | D75: Hotel / hospedaje | F75: 3146019734 | G75: LA HABANA | H75: 46314 | I75: Sin señal de actualización específica en el registro fuente; verificar vigencia. | J75: https://www.datos.gov.co/w/m463-yj48/dneh-mcp2 | K75: Registro del directorio público de hoteles; confirmar vigencia y datos antes de contactar. Dirección conservada en el formato abreviado de la fuente. | Fuente: Prospectos_NeXo_La_Dorada.xlsx | L75: =IF($B75="","",SUBSTITUTE(INDEX(Plantillas!$B$6:$B$15,MATCH($C75,Plantillas!$A$6:$A$15,0)),"{NEGOCIO}",$B75)) | M75: =IF($B75="","",SUBSTITUTE(INDEX(Plantillas!$C$6:$C$15,MATCH($C75,Plantillas!$A$6:$A$15,0)),"{NEGOCIO}",$B75)) | N75: Sin correo público | O75: Pendiente de revisar | P75: Pendiente de revisión | S75: Pendiente
A76: NX-072 | B76: CABAÑA VILLA HERMOSA | C76: Hoteles y hospedajes | D76: Hotel / hospedaje | F76: 3206361169 | G76: LA HABANA | H76: 46314 | I76: Sin señal de actualización específica en el registro fuente; verificar vigencia. | J76: https://www.datos.gov.co/w/m463-yj48/dneh-mcp2 | K76: Registro del directorio público de hoteles; confirmar vigencia y datos antes de contactar. Dirección conservada en el formato abreviado de la fuente. | Fuente: Prospectos_NeXo_La_Dorada.xlsx | L76: =IF($B76="","",SUBSTITUTE(INDEX(Plantillas!$B$6:$B$15,MATCH($C76,Plantillas!$A$6:$A$15,0)),"{NEGOCIO}",$B76)) | M76: =IF($B76="","",SUBSTITUTE(INDEX(Plantillas!$C$6:$C$15,MATCH($C76,Plantillas!$A$6:$A$15,0)),"{NEGOCIO}",$B76)) | N76: Sin correo público | O76: Pendiente de revisar | P76: Pendiente de revisión | S76: Pendiente
A77: NX-073 | B77: CABAÑA SOL Y MIEL | C77: Hoteles y hospedajes | D77: Hotel / hospedaje | E77: ov870904@gmail.com | F77: 3108237675 | G77: LA HABANA | H77: 46314 | I77: Sin señal de actualización específica en el registro fuente; verificar vigencia. | J77: https://www.datos.gov.co/w/m463-yj48/dneh-mcp2 | K77: Registro del directorio público de hoteles; confirmar vigencia y datos antes de contactar. Dirección conservada en el formato abreviado de la fuente. | Fuente: Prospectos_NeXo_La_Dorada.xlsx | L77: =IF($B77="","",SUBSTITUTE(INDEX(Plantillas!$B$6:$B$15,MATCH($C77,Plantillas!$A$6:$A$15,0)),"{NEGOCIO}",$B77)) | M77: =IF($B77="","",SUBSTITUTE(INDEX(Plantillas!$C$6:$C$15,MATCH($C77,Plantillas!$A$6:$A$15,0)),"{NEGOCIO}",$B77)) | N77: Pendiente de verificar | O77: Pendiente de revisar | P77: Pendiente de revisión | S77: Pendiente
A78: NX-074 | B78: HOTEL LA PARCELA | C78: Hoteles y hospedajes | D78: Hotel / hospedaje | E78: holamillo@gmail.com | F78: 3148357836 | G78: GUARINOCITO | H78: 46314 | I78: Sin señal de actualización específica en el registro fuente; verificar vigencia. | J78: https://www.datos.gov.co/w/m463-yj48/dneh-mcp2 | K78: Registro del directorio público de hoteles; confirmar vigencia y datos antes de contactar. Dirección conservada en el formato abreviado de la fuente. | Fuente: Prospectos_NeXo_La_Dorada.xlsx | L78: =IF($B78="","",SUBSTITUTE(INDEX(Plantillas!$B$6:$B$15,MATCH($C78,Plantillas!$A$6:$A$15,0)),"{NEGOCIO}",$B78)) | M78: =IF($B78="","",SUBSTITUTE(INDEX(Plantillas!$C$6:$C$15,MATCH($C78,Plantillas!$A$6:$A$15,0)),"{NEGOCIO}",$B78)) | N78: Pendiente de verificar | O78: Pendiente de revisar | P78: Pendiente de revisión | S78: Pendiente
A79: NX-075 | B79: RESIDENCIAS MONACO | C79: Hoteles y hospedajes | D79: Hotel / hospedaje | F79: 3148569021 | G79: K 6 14 26 | H79: 46314 | I79: Sin señal de actualización específica en el registro fuente; verificar vigencia. | J79: https://www.datos.gov.co/w/m463-yj48/dneh-mcp2 | K79: Registro del directorio público de hoteles; confirmar vigencia y datos antes de contactar. Dirección conservada en el formato abreviado de la fuente. | Fuente: Prospectos_NeXo_La_Dorada.xlsx | L79: =IF($B79="","",SUBSTITUTE(INDEX(Plantillas!$B$6:$B$15,MATCH($C79,Plantillas!$A$6:$A$15,0)),"{NEGOCIO}",$B79)) | M79: =IF($B79="","",SUBSTITUTE(INDEX(Plantillas!$C$6:$C$15,MATCH($C79,Plantillas!$A$6:$A$15,0)),"{NEGOCIO}",$B79)) | N79: Sin correo público | O79: Pendiente de revisar | P79: Pendiente de revisión | S79: Pendiente
A80: NX-076 | B80: RESIDENCIAS ROMA | C80: Hoteles y hospedajes | D80: Hotel / hospedaje | F80: 3218469765 | G80: K 3 16 37 | H80: 46314 | I80: Sin señal de actualización específica en el registro fuente; verificar vigencia. | J80: https://www.datos.gov.co/w/m463-yj48/dneh-mcp2 | K80: Registro del directorio público de hoteles; confirmar vigencia y datos antes de contactar. Dirección conservada en el formato abreviado de la fuente. | Fuente: Prospectos_NeXo_La_Dorada.xlsx | L80: =IF($B80="","",SUBSTITUTE(INDEX(Plantillas!$B$6:$B$15,MATCH($C80,Plantillas!$A$6:$A$15,0)),"{NEGOCIO}",$B80)) | M80: =IF($B80="","",SUBSTITUTE(INDEX(Plantillas!$C$6:$C$15,MATCH($C80,Plantillas!$A$6:$A$15,0)),"{NEGOCIO}",$B80)) | N80: Sin correo público | O80: Pendiente de revisar | P80: Pendiente de revisión | S80: Pendiente
A81: NX-077 | B81: LA AURORA FAMILIAR | C81: Hoteles y hospedajes | D81: Hotel / hospedaje | E81: hotelfamiliarlaaurora@hotmail.com | F81: 3113094800 | G81: K 6 46 18 | H81: 46314 | I81: Sin señal de actualización específica en el registro fuente; verificar vigencia. | J81: https://www.datos.gov.co/w/m463-yj48/dneh-mcp2 | K81: Registro del directorio público de hoteles; confirmar vigencia y datos antes de contactar. Dirección conservada en el formato abreviado de la fuente. | Fuente: Prospectos_NeXo_La_Dorada.xlsx | L81: =IF($B81="","",SUBSTITUTE(INDEX(Plantillas!$B$6:$B$15,MATCH($C81,Plantillas!$A$6:$A$15,0)),"{NEGOCIO}",$B81)) | M81: =IF($B81="","",SUBSTITUTE(INDEX(Plantillas!$C$6:$C$15,MATCH($C81,Plantillas!$A$6:$A$15,0)),"{NEGOCIO}",$B81)) | N81: Pendiente de verificar | O81: Pendiente de revisar | P81: Pendiente de revisión | S81: Pendiente
A82: NX-078 | B82: LAS ACACIAS DE CALDAS | C82: Hoteles y hospedajes | D82: Hotel / hospedaje | E82: tatto55_@gmail.com | F82: 3107488357 | G82: C 14 5 31 | H82: 46314 | I82: Sin señal de actualización específica en el registro fuente; verificar vigencia. | J82: https://www.datos.gov.co/w/m463-yj48/dneh-mcp2 | K82: Registro del directorio público de hoteles; confirmar vigencia y datos antes de contactar. Dirección conservada en el formato abreviado de la fuente. | Fuente: Prospectos_NeXo_La_Dorada.xlsx | L82: =IF($B82="","",SUBSTITUTE(INDEX(Plantillas!$B$6:$B$15,MATCH($C82,Plantillas!$A$6:$A$15,0)),"{NEGOCIO}",$B82)) | M82: =IF($B82="","",SUBSTITUTE(INDEX(Plantillas!$C$6:$C$15,MATCH($C82,Plantillas!$A$6:$A$15,0)),"{NEGOCIO}",$B82)) | N82: Pendiente de verificar | O82: Pendiente de revisar | P82: Pendiente de revisión | S82: Pendiente
...

Sheet Plantillas
A2: Plantillas de correo por sector
A3: Edita aquí; {NEGOCIO} se reemplaza automáticamente en Contactos.
A5: Categoría de contacto | B5: Asunto modelo | C5: Cuerpo modelo (texto plano) | D5: Sectores incluidos
A6: Hoteles y hospedajes | B6: Soporte para impresoras y computadores en {NEGOCIO} | C6: Hola, equipo de {NEGOCIO}: Somos NeXo, una empresa tecnológica de La Dorada. Apoyamos a hoteles y hospedajes con mantenimiento y reparación de impresoras de distintas marcas y tecnologías, soporte para computadores e insumos de impresión. También desarrollamos páginas web y automatizaciones que pueden ayudar a organizar procesos del negocio. ¿Quién coordina el soporte de estos equipos? Si les interesa, podemos presentarnos y coordinar una visita breve para conocer sus necesidades. Atentamente, Equipo NeXo Soluciones tecnológicas y servicio técnico | La Dorada, Caldas WhatsApp: +57 322 206 7870 Sitio web: https://ne-xo-page.vercel.app Si prefieren no recibir más información comercial, pueden responder a este correo y lo tendremos en cuenta. | D6: Hoteles, hospedajes, apartahoteles y alojamientos.
A7: Salud y atención médica | B7: Mantenimiento tecnológico para {NEGOCIO} | C7: Cordial saludo, equipo de {NEGOCIO}: Somos NeXo, empresa tecnológica de La Dorada. Ofrecemos mantenimiento preventivo y correctivo de impresoras láser, de tinta y multifuncionales, además de soporte para computadores. Podemos coordinar la atención para conocer sus equipos y las necesidades de su área administrativa. ¿Quién coordina el mantenimiento de impresoras y computadores en la institución? Nos gustaría presentarles nuestros servicios y acordar una visita breve, si lo consideran conveniente. Atentamente, Equipo NeXo Soluciones tecnológicas y servicio técnico | La Dorada, Caldas WhatsApp: +57 322 206 7870 Sitio web: https://ne-xo-page.vercel.app Si prefieren no recibir más información comercial, pueden responder a este correo y lo tendremos en cuenta. | D7: Hospitales, clínicas, centros médicos, odontología y prestadores de salud.
A8: Educación e instituciones | B8: Soporte de impresión y computadores para {NEGOCIO} | C8: Cordial saludo, equipo de {NEGOCIO}: Somos NeXo, una empresa tecnológica de La Dorada. Brindamos mantenimiento y reparación de impresoras de diferentes marcas y tecnologías, y soporte para computadores portátiles y de escritorio. También desarrollamos páginas web, software y automatizaciones para apoyar procesos institucionales. ¿Quién coordina el mantenimiento de estos equipos? Nos gustaría presentarles nuestros servicios y, si les resulta útil, coordinar una visita breve. Atentamente, Equipo NeXo Soluciones tecnológicas y servicio técnico | La Dorada, Caldas WhatsApp: +57 322 206 7870 Sitio web: https://ne-xo-page.vercel.app Si prefieren no recibir más información comercial, pueden responder a este correo y lo tendremos en cuenta. | D8: Instituciones educativas, colegios y universidades.
A9: Papelerías, copias e impresión | B9: Aliado técnico para impresión e insumos | NeXo | C9: Hola, equipo de {NEGOCIO}: Somos NeXo, empresa tecnológica de La Dorada. Ofrecemos mantenimiento y reparación de impresoras láser, de tinta continua, de cartucho y multifuncionales. También contamos con insumos para impresión a precios competitivos y brindamos soporte a computadores. Nos gustaría conocer sus necesidades y presentarles opciones para apoyar la operación de su negocio. ¿Con quién podríamos coordinar una conversación o visita breve? Atentamente, Equipo NeXo Soluciones tecnológicas y servicio técnico | La Dorada, Caldas WhatsApp: +57 322 206 7870 Sitio web: https://ne-xo-page.vercel.app Si prefieren no recibir más información comercial, pueden responder a este correo y lo tendremos en cuenta. | D9: Papelerías, librerías, copiado, litografía, impresión y publicidad impresa.
A10: Belleza y cuidado personal | B10: Apoyo tecnológico para {NEGOCIO} | C10: Hola, equipo de {NEGOCIO}: Somos NeXo, empresa tecnológica de La Dorada. Si en su negocio utilizan computadores o impresoras para la atención y administración, podemos apoyarles con diagnóstico, mantenimiento y reparación. También creamos páginas web y automatizaciones a la medida para negocios y empresas. ¿Quién coordina estos temas? Si les parece, podemos conversar brevemente y explorar qué solución les sería útil. Atentamente, Equipo NeXo Soluciones tecnológicas y servicio técnico | La Dorada, Caldas WhatsApp: +57 322 206 7870 Sitio web: https://ne-xo-page.vercel.app Si prefieren no recibir más información comercial, pueden responder a este correo y lo tendremos en cuenta. | D10: Peluquerías, barberías, uñas, spa, pestañas, cosmética y belleza.
A11: Moda, calzado y accesorios | B11: Servicios tecnológicos para {NEGOCIO} | C11: Hola, equipo de {NEGOCIO}: Somos NeXo, empresa tecnológica de La Dorada. Brindamos mantenimiento y soporte para impresoras y computadores, y desarrollamos páginas web, software y automatizaciones para negocios. Podemos conocer sus necesidades y proponer opciones prácticas para sus procesos administrativos y su presencia digital. ¿Con quién podríamos conversar sobre el soporte tecnológico de su negocio? Estamos disponibles para una presentación breve. Atentamente, Equipo NeXo Soluciones tecnológicas y servicio técnico | La Dorada, Caldas WhatsApp: +57 322 206 7870 Sitio web: https://ne-xo-page.vercel.app Si prefieren no recibir más información comercial, pueden responder a este correo y lo tendremos en cuenta. | D11: Boutiques, ropa, calzado, accesorios, talabarterías y sastrerías.
A12: Alimentos, tiendas y consumo | B12: Soporte para computadores e impresión en {NEGOCIO} | C12: Hola, equipo de {NEGOCIO}: Somos NeXo, una empresa tecnológica de La Dorada. Ofrecemos mantenimiento y reparación de impresoras y soporte para computadores. Además, desarrollamos páginas web, software y automatizaciones ajustadas a las necesidades de cada negocio. ¿Quién coordina el soporte tecnológico? Nos gustaría presentarles nuestros servicios y saber si podemos ayudarles con algún equipo o proceso. Atentamente, Equipo NeXo Soluciones tecnológicas y servicio técnico | La Dorada, Caldas WhatsApp: +57 322 206 7870 Sitio web: https://ne-xo-page.vercel.app Si prefieren no recibir más información comercial, pueden responder a este correo y lo tendremos en cuenta. | D12: Tiendas, supermercados, panaderías, alimentos y comercios de consumo.
A13: Comercios y corresponsales | B13: Soluciones tecnológicas para {NEGOCIO} | C13: Hola, equipo de {NEGOCIO}: Somos NeXo, empresa tecnológica de La Dorada. Apoyamos a negocios locales con mantenimiento de impresoras, soporte para computadores y suministro de insumos de impresión. También desarrollamos páginas web, software y automatizaciones a la medida. ¿Quién coordina estos servicios en su negocio? Podemos presentarnos y conocer sus necesidades en una conversación breve. Atentamente, Equipo NeXo Soluciones tecnológicas y servicio técnico | La Dorada, Caldas WhatsApp: +57 322 206 7870 Sitio web: https://ne-xo-page.vercel.app Si prefieren no recibir más información comercial, pueden responder a este correo y lo tendremos en cuenta. | D13: Corresponsales, misceláneas, variedades, tiendas y comercio minorista.
A14: Bienestar y entrenamiento | B14: Soporte digital y tecnológico para {NEGOCIO} | C14: Hola, equipo de {NEGOCIO}: Somos NeXo, una empresa tecnológica de La Dorada. Ofrecemos soporte para computadores e impresoras y creamos páginas web y automatizaciones que pueden ayudar a organizar procesos de negocios dedicados al bienestar y el entrenamiento. ¿Quién coordina el soporte tecnológico o los proyectos digitales? Nos gustaría presentarles brevemente nuestros servicios y conocer sus necesidades. Atentamente, Equipo NeXo Soluciones tecnológicas y servicio técnico | La Dorada, Caldas WhatsApp: +57 322 206 7870 Sitio web: https://ne-xo-page.vercel.app Si prefieren no recibir más información comercial, pueden responder a este correo y lo tendremos en cuenta. | D14: Gimnasios, entrenamiento y bienestar.
A15: Empresas y servicios | B15: Presentación de servicios tecnológicos | NeXo | C15: Cordial saludo, equipo de {NEGOCIO}: Somos NeXo, una empresa tecnológica de La Dorada. Prestamos mantenimiento y reparación de impresoras de distintas marcas y tecnologías, soporte para computadores, y desarrollamos software, páginas web y automatizaciones para empresas e instituciones. ¿Quién coordina el soporte de impresoras y computadores o los proyectos de tecnología? Nos gustaría presentarles nuestros servicios y conocer sus necesidades. Atentamente, Equipo NeXo Soluciones tecnológicas y servicio técnico | La Dorada, Caldas WhatsApp: +57 322 206 7870 Sitio web: https://ne-xo-page.vercel.app Si prefieren no recibir más información comercial, pueden responder a este correo y lo tendremos en cuenta. | D15: Empresas, servicios profesionales, comercio mayorista, transporte, construcción, finanzas, logística y otros sectores.

Sheet Clasificación
A2: Mapa de categorías
A3: Referencia editable: cada sector de origen se agrupa en una categoría para filtrar la base. Si una clasificación no encaja, cambia la categoría en Contactos.
A5: Sector según fuente | B5: Categoría de contacto | C5: Negocios en esta categoría fuente
A6: Accesorios / ropa | B6: Moda, calzado y accesorios | C6: 1
A7: Alimentos / corresponsal | B7: Alimentos, tiendas y consumo | C7: 1
A8: Alimentos / repostería | B8: Alimentos, tiendas y consumo | C8: 1
A9: Automotor / revisión técnico-mecánica | B9: Empresas y servicios | C9: 1
A10: Barbería | B10: Belleza y cuidado personal | C10: 6
A11: Belleza / cosméticos / accesorios | B11: Belleza y cuidado personal | C11: 1
A12: Belleza / peluquería | B12: Belleza y cuidado personal | C12: 1
A13: Belleza / pestañas | B13: Belleza y cuidado personal | C13: 1
A14: Belleza / spa | B14: Belleza y cuidado personal | C14: 1
A15: Belleza / uñas | B15: Belleza y cuidado personal | C15: 4
A16: Belleza / uñas / peluquería | B16: Belleza y cuidado personal | C16: 1
A17: Calzado / zapatería | B17: Moda, calzado y accesorios | C17: 2
... A74: Variedades / corresponsal | B74: Comercios y corresponsales | C74: 6
